Workbook
Name B_Critical: #N/A
Name Blocker: #N/A
Name Browser_list: 'Testing Plan'!$B$12:$B$22
Name Build_Number: OFFSET('Build Info'!$C$3,0,0,1,COUNTA('Build Info'!$3:$3)-2)
Name Environment_OS: 'Testing Plan'!$B$3:$B$11
Name Major: OFFSET(Build_Number,50,0)
Name Minor: OFFSET('Build Info'!Build_Number,51,0)
Name Project_URL: 'Testing Plan'!$K$3:$K$24
Name Quality: OFFSET('Build Info'!Build_Number,8,0)
Name Quality_range: Description!$A$92:$A$98
Name Size: OFFSET('Build Info'!Build_Number,6,0)
Name Test_coverage: Description!$B$11:$B$13
Name Test_status: Description!$A$79:$A$88
Name Test_Team: 'Testing Plan'!$H$3:$H$24
Name Test_types: Description!$B$11:$B$19
Name Trivial: OFFSET('Build Info'!Build_Number,52,0)

Sheet Description
A1: No Need to Edit (EXAMPLE)
A2: "Project name" Acceptance Sheet Document
A3: The Acceptance Sheet contains information about all tests and their results.
A4: An acceptance sheet should be sent as an attach to PM, TM and PC after the MAT, the New Features Testing (if an acceptance test will not be executed) and the Acceptance Test.
A5: A common description of the quality of the build in accordance with last testing type should be included in such letters.
A7: Build Info & Testing tabs description
A9: Build Information
A10: Build Number | B10: The number of the build that was tested.
A11: Test type | B11: Smoke Test | C11: A subset of all defined/planned test cases that cover the main functionality of a component or system, to ascertaining that the most crucial functions of a program work, but not bothering with finer details.
B12: MAT | C12: Minimal Acceptance Test: A test directed to check that all application functions can be performed with correct data. Check if all application features can be used under correct conditions. For complex and large applications, a limited set of functions and scenarios is used.
B13: AT | C13: Full Acceptance Test: A test directed to verify that the software can be used by end users to perform the functions and tasks for which the software was built under any conditions. Business logic + functionality + form behaviour + GUI test + Usability test + localisation test (if applicable) — a complete test of the functionality and interface under any conditions (positive and negative testing). All these tests make up a maximal set for testing, but it can also comprise one or several parts (depending on the end-users aims while using the product).
B14: NFT | C14: Full Acceptance Test of New Features: A test directed to verify if the feature is completely and correctly implemented and if the logic of the product is not affected. Check if all application features can be used under correct conditions. For complex and large applications, a limited set of functions and scenarios is used.
B15: DV | C15: Defects Validation: A test directed to check all the defects that were resolved against the current build. Testing of the feature that contained the fixed defect.
B16: Regression Test | C16: Testing of a previously tested program following modification to ensure that defects have not been introduced or uncovered in unchanged areas of the software, as a result of the changes made. It is performed when the software or its environment is changed.
B17: Crossbrowser Test | C17: Testing of the program to determine if it's functional on different internet browsers.
C18: Add test type if it's not on the list.
C19: Add test type if it's not on the list.
A20: Test date | B20: Date range when the tests were performed.
A21: Tester | B21: Testers who performed tests.
A22: Environment / OS | B22: Environment / OS on which the tests were performed.
A23: Browser | B23: Browser on which the tests were performed.
A24: Project Size | B24: Subjective metric set for the first build by QA Manager for further tracking of quality.
A25: Quality | B25: Subjective quality rate of the build.
A26: Quality rate | B26: Calculated quality rate of the build.
A27: Total defects quantity | B27: Quantity of all active defects in Jira by the end of testing.
A28: New defects quantity | B28: Quantity of active defects in Jira by the end of testing found in the current build.
A29: Comments | B29: Any comments that are needed.
A32: New defects found
A33: New defects quantity | B33: Quantity of active defects by the end of testing found in the current build.
A34: With high severity | B34: Quantity of active defects with high severity (Average, Major, Critical) by the end of testing found in the current build.
A35: Comments | B35: Any comments that are needed.
A38: Jira defects status report
A39: Open | B39: Quantity of defects having "Open" state by the end of testing (the issue is open and ready for the assignee to start work on it).
A40: In Progress | B40: Quantity of defects having "In Progress" state by the end of testing (this issue is being actively worked on at the moment by the assignee).
A41: Resolved | B41: Quantity of defects having "Resolved" state by the end of testing (A resolution has been taken, and it is awaiting verification by reporter. From here issues are either reopened, or are closed).
A42: Postponed | B42: Quantity of defects having "Postponed" state by the end of testing.
A43: To be reformulated | B43: Quantity of defects having "To be reformulated" state by the end of testing.
A44: Total | B44: Total quantity of active defects in JIRA.
A45: Comments | B45: Any comments that are needed.
A48: Defect validation report
...

Sheet Build Info
A1: No Need to Edit (EXAMPLE)
A2: Build Information | J2: Required
A3: Build number | B3: 1 | C3: 1 | D3: 2 | E3: 2 | F3: 2 | J3: 3
A4: Test type | B4: Smoke Test | C4: AT | D4: Smoke Test | E4: DV | F4: Regression Test | J4: 3
A5: Test date | B5: 41213 | C5: 11-12.06.2012 | D5: 41213 | E5: 41191 | F5: 41214 | J5: 3
A6: Tester | B6: O. Kot | C6: O. Kot | D6: O. Kot | E6: O. Kot | F6: O. Kot | J6: 3
A7: Environment / OS | B7: Win 7 | C7: Win 7 | D7: Win 7 | E7: Win 7 | F7: Win 7
A8: Browser | B8: IE 9 | C8: IE 9 | D8: IE 9 | E8: IE 9 | F8: IE 9
A9: Project size | B9: 100 | C9: 100 | D9: 100 | E9: 100 | F9: 100
A10: Quality | B10: Acceptable | C10: Low | D10: Acceptable | E10: Medium | F10: Below Medium | J10: 3
A11: Quality rate | B11: =ROUND(EXP(-1*(100*B51+20*B52+4*B53+2*B54+1*B55)/B9),3) -> 1 | C11: =ROUND(EXP(-1*(100*C51+20*C52+4*C53+2*C54+1*C55)/C9),3) -> 0.068 | D11: =ROUND(EXP(-1*(100*D51+20*D52+4*D53+2*D54+1*D55)/D9),3) -> 0.068 | E11: =ROUND(EXP(-1*(100*E51+20*E52+4*E53+2*E54+1*E55)/E9),3) -> 0.527 | F11: =ROUND(EXP(-1*(100*F51+20*F52+4*F53+2*F54+1*F55)/F9),3) -> 0.375 | J11: 3
A12: Total defects quantity | B12: 0 | C12: 52 | D12: 52 | E12: 22 | F12: 32 | J12: 3
A13: New defects quantity | B13: 0 | C13: 52 | D13: 0 | E13: 0 | F13: 10
A14: Comments
A16: Statistics for Defects
A18: New defects found:
A19: New defects quantity | B19: 0 | C19: 52 | D19: 0 | E19: 0 | F19: 10
A20: With high severity | B20: 0 | C20: 8 | D20: 0 | E20: 0 | F20: 0
A21: Comments
A23: Jira defects status report: | J23: 3
A24: Open | B24: 0 | C24: 52 | D24: 17 | E24: 17 | F24: 27
A25: In Progress | B25: 0 | C25: 0 | D25: 5 | E25: 5 | F25: 5
A26: Resolved | B26: 0 | C26: 0 | D26: 30 | E26: 0 | F26: 0
A27: Postponed | B27: 0 | C27: 0 | D27: 0 | E27: 0 | F27: 0
A28: To be reformulated | B28: 0 | C28: 0 | D28: 0 | E28: 0 | F28: 0
A29: Total | B29: =SUM(B24:B28) -> 0 | C29: =SUM(C24:C28) -> 52 | D29: =SUM(D24:D28) -> 52 | E29: =SUM(E24:E28) -> 22 | F29: =SUM(F24:F28) -> 32
A30: Comments
A32: Defect validation report: | J32: 3
A33: Number of checked defects | B33: – | C33: – | D33: – | E33: 30 | F33: –
A34: Reject: Critical | B34: – | C34: – | D34: – | E34: 0 | F34: –
A35: Reject: Major | B35: – | C35: – | D35: – | E35: 0 | F35: –
A36: Reject: Average | B36: – | C36: – | D36: – | E36: 1 | F36: –
A37: Reject: Minor | B37: – | C37: – | D37: – | E37: 3 | F37: –
A38: Reject: Enhancement | B38: – | C38: – | D38: – | E38: 0 | F38: –
A39: Not checked | B39: – | C39: – | D39: – | E39: 1 | F39: –
A40: Percent of Rejects | E40: =SUM(E34:E39)/(E33+E39) -> 0.16129032
A41: Comments
A43: CR validation report:
A44: Number of checked CRs | B44: – | C44: – | D44: – | E44: – | F44: –
A45: Rejected | B45: – | C45: – | D45: – | E45: – | F45: –
...

Sheet Front End
B1: Build | E1: 1
B2: Test type | E2: AT
B3: Test date | E3: 10-12.03.2026
B4: Tester | E4: Md. Akramul Islam
B5: Project Environment | E5: http://80.249.129.99:58363/
B6: Operating System | E6: Win 11 pro
B7: Browser | E7: Google Chrome Version 146.0.7680.72
B8: Project Information | E8: Test Cases Statistics
B9: Project name | C9: GregOlsen.PhotoStudio | E9: Status | F9: Quantity | G9: Percentage (%)
B10: Project URL | C10: http://80.249.129.99:58363/ | E10: OK | F10: =COUNTIF('Front End'!E$22:E$156,"OK") -> 21 | G10: =IF(ISERROR(F10/F20),"",F10/F20) -> 0.2625
E11: Partially tested | F11: =COUNTIF('Front End'!E$22:E$156,"Partially tested") -> 0 | G11: =IF(ISERROR(F11/F20),"",F11/F20) -> 0
E12: Enhancement | F12: =COUNTIF('Front End'!E$27:E$156,"Enhancement") -> 0 | G12: =IF(ISERROR(F12/F20),"",F12/F20) -> 0
E13: Minor | F13: =COUNTIF('Front End'!E$22:E$156,"Minor") -> 16 | G13: =IF(ISERROR(F13/F20),"",F13/F20) -> 0.2
E14: Average | F14: =COUNTIF('Front End'!E$22:E$156,"Average") -> 5 | G14: =IF(ISERROR(F14/F20),"",F14/F20) -> 0.0625
E15: Major | F15: =COUNTIF('Front End'!E$22:E$156,"Major") -> 22 | G15: =IF(ISERROR(F15/F20),"",F15/F20) -> 0.275
E16: Critical | F16: =COUNTIF('Front End'!E$22:E$156,"Critical") -> 1 | G16: =IF(ISERROR(F16/F20),"",F16/F20) -> 0.0125
E17: Not available | F17: =COUNTIF('Front End'!E$22:E$156,"Not available") -> 14 | G17: =IF(ISERROR(F17/F20),"",F17/F20) -> 0.175
E18: Not implemented | F18: =COUNTIF('Front End'!E$22:E$156,"Not implemented") -> 1 | G18: =IF(ISERROR(F18/F20),"",F18/F20) -> 0.0125
E19: Not tested | F19: =COUNTIF('Front End'!E$22:E$156,"Not tested") -> 0 | G19: =IF(ISERROR(F19/F20),"",F19/F20) -> 0
E20: Total cases | F20: =COUNTA('Front End'!E$22:E$156) -> 80
A21: Test type | B21: Module | C21: Submodule | E21: Result | F21: Issues | G21: Comments
B22: Header
C23: Title tab
A24: AT | D24: GUI | E24: Minor
A25: AT | C25: Navigation
A26: AT | D26: GUI | E26: Minor
A27: AT | D27: Fun: Fixed Position | E27: OK
A28: Smoke Test | D28: Fun: Menu Link and Order | E28: Major
A29: AT | C29: Search
A30: AT | D30: GUI | E30: Minor
A31: Smoke Test | D31: Fun: Display search results | E31: Major
B32: Footer
A33: AT | D33: GUI | E33: Minor
A34: Smoke Test | D34: Fun: External Link Redirection | E34: OK
B35: Home
A36: AT | C36: Demo
A37: AT | D37: GUI | E37: OK
A38: AT | D38: Fun: Image swapping | E38: OK
A39: Smoke Test | D39: Fun: Gallery redirection links | E39: Not implemented
A40: AT | C40: Question-Answer Zone
...

Sheet Testing Plan
A1: No Need to Edit (EXAMPLE)
A2: Requirement | B2: Software | C2: Comments | H2: Test Team | J2: Project Environment | K2: URL
A3: Environment / Operating System | B3: Win 7
E4: 6.8 %
C10: Add environment / operating system if it's not on the list.
C11: Add environment / operating system if it's not on the list.
A12: Browser | B12: — | C12: Used for testing environment with built-in browser (e.g. in Android system).
E14: 6.8 %
B17: Chrome 134
C21: Add browser if it's not on the list.
C22: Add browser if it's not on the list.
A23: Language: English
A27: Main Test Condition
A28: OS | B28: Win 7
A29: Browser | B29: IE 9
A30: Additional Test Plan
A31: OS | B31: Browser | C31: Build Number | D31: Test Type | E31: Test date | F31: Quality
A32: Win 7 | B32: — | C32: 1 | D32: AT | E32: 04 – 05.12.2024 | F32: Low
